Workbook

Sheet FILTERING OUT TOPICS
A1: Topic ID | B1: Topic ID no url | D1: Topic name | E1: Concat 2 | F1: OA field | G1: OA domain | H1: Code | I1: Claude categorisation | J1: Should we keep this OA topic? | K1: Claude Recommendation | L1: Number of articles (OpenAlex GBQ) | M1: Number of CORDIS projects | N1: Peak score | O1: Top-Q count | P1: Average frontierness | Q1: Frontier 2004-2007 | R1: Frontier 2008-2011 | S1: Frontier 2012-2015 | T1: Frontier 2016-2019 | U1: Frontier 2020-2023 | V1: Frontier 2024-2025 | W1: Best period
A2: https://openalex.org/T13703 | B2: =RIGHT(A2, LEN(A2) - FIND("/T", A2)) -> T13703 | C2: =CONCAT(B2, ",") -> T13703, | D2: Attention Economy in Education and Business | E2: =CONCATENATE(B2," ",D2,",") -> T13703 Attention Economy in Education and Business, | F2: Business, Management and Accounting | G2: Social Sciences | H2: E | I2: Education & pedagogy | J2: Filter out | K2: Filter | L2: 907 | M2: =VLOOKUP(A2,'Matching with Cordis'!A$2:D$3447, 4, FALSE) -> 117 | N2: 0.675 | O2: 2 | P2: =AVERAGE(Q2:V2) -> -0.3155 | Q2: 0.392 | R2: -0.592 | S2: -0.338 | T2: 0.675 | U2: -1.653 | V2: -0.377 | W2: 2016-2019
A3: https://openalex.org/T13436 | B3: =RIGHT(A3, LEN(A3) - FIND("/T", A3)) -> T13436 | C3: =CONCAT(B3, ",") -> T13436, | D3: Space Technology and Applications | E3: =CONCATENATE(B3," ",D3,",") -> T13436 Space Technology and Applications, | F3: Engineering | G3: Physical Sciences | H3: S | I3: Core S&T | J3: Filter out | K3: Keep | L3: 1254 | M3: =VLOOKUP(A3,'Matching with Cordis'!A$2:D$3447, 4, FALSE) -> 74 | N3: 1.156 | O3: 4 | P3: =AVERAGE(Q3:V3) -> 0.2865 | Q3: 0.317 | R3: 0.354 | S3: 1.004 | T3: -0.692 | U3: -0.42 | V3: 1.156 | W3: 2024-2025
A4: https://openalex.org/T13656 | B4: =RIGHT(A4, LEN(A4) - FIND("/T", A4)) -> T13656 | C4: =CONCAT(B4, ",") -> T13656, | D4: Science, Research, and Medicine | E4: =CONCATENATE(B4," ",D4,",") -> T13656 Science, Research, and Medicine, | F4: Medicine | G4: Health Sciences | H4: X | I4: Catch-all / vague | J4: Filter out | K4: Filter | L4: 44911 | M4: =VLOOKUP(A4,'Matching with Cordis'!A$2:D$3447, 4, FALSE) -> 74 | N4: 0.512 | O4: 1 | P4: =AVERAGE(Q4:V4) -> -0.19933333 | Q4: -0.57 | R4: -0.392 | S4: -0.17 | T4: -0.429 | U4: -0.147 | V4: 0.512 | W4: 2024-2025
A5: https://openalex.org/T10289 | B5: =RIGHT(A5, LEN(A5) - FIND("/T", A5)) -> T10289 | C5: =CONCAT(B5, ",") -> T10289, | D5: European Union Policy and Governance | E5: =CONCATENATE(B5," ",D5,",") -> T10289 European Union Policy and Governance, | F5: Social Sciences | G5: Social Sciences | H5: P | I5: Social science & policy | J5: Filter out | K5: Review | L5: 86922 | M5: =VLOOKUP(A5,'Matching with Cordis'!A$2:D$3447, 4, FALSE) -> 72 | N5: -0.196 | O5: 0 | P5: =AVERAGE(Q5:V5) -> -0.44966667 | Q5: -0.196 | R5: -0.485 | S5: -0.433 | T5: -0.44 | U5: -0.773 | V5: -0.371 | W5: 2004-2007
A6: https://openalex.org/T14152 | B6: =RIGHT(A6, LEN(A6) - FIND("/T", A6)) -> T14152 | C6: =CONCAT(B6, ",") -> T14152, | D6: Healthcare Facilities Design and Sustainability | E6: =CONCATENATE(B6," ",D6,",") -> T14152 Healthcare Facilities Design and Sustainability, | F6: Social Sciences | G6: Social Sciences | H6: P | I6: Social science & policy | J6: Filter out | K6: Review | L6: 1893 | M6: =VLOOKUP(A6,'Matching with Cordis'!A$2:D$3447, 4, FALSE) -> 66 | N6: 1.389 | O6: 6 | P6: =AVERAGE(Q6:V6) -> 0.97016667 | Q6: 1.389 | R6: 0.885 | S6: 0.963 | T6: 0.809 | U6: 1.089 | V6: 0.686 | W6: 2004-2007
A7: https://openalex.org/T14347 | B7: =RIGHT(A7, LEN(A7) - FIND("/T", A7)) -> T14347 | C7: =CONCAT(B7, ",") -> T14347, | D7: Big Data and Digital Economy | E7: =CONCATENATE(B7," ",D7,",") -> T14347 Big Data and Digital Economy, | F7: Computer Science | G7: Physical Sciences | H7: S | I7: Core S&T | J7: Filter out | K7: Keep | L7: 1572 | M7: =VLOOKUP(A7,'Matching with Cordis'!A$2:D$3447, 4, FALSE) -> 59 | N7: 4.479 | O7: 6 | P7: =AVERAGE(Q7:V7) -> 2.4516667 | Q7: 4.479 | R7: 0.694 | S7: 3.634 | T7: 2.471 | U7: 1.661 | V7: 1.771 | W7: 2004-2007
A8: https://openalex.org/T14440 | B8: =RIGHT(A8, LEN(A8) - FIND("/T", A8)) -> T14440 | C8: =CONCAT(B8, ",") -> T14440, | D8: Quality of Life Measurement | E8: =CONCATENATE(B8," ",D8,",") -> T14440 Quality of Life Measurement, | F8: Social Sciences | G8: Social Sciences | H8: P | I8: Social science & policy | J8: Filter out | K8: Review | L8: 1711 | M8: =VLOOKUP(A8,'Matching with Cordis'!A$2:D$3447, 4, FALSE) -> 53 | N8: 1.745 | O8: 5 | P8: =AVERAGE(Q8:V8) -> 0.8545 | Q8: 0.231 | R8: 1.334 | S8: 1.745 | T8: 0.978 | U8: 0.454 | V8: 0.385 | W8: 2012-2015
A9: https://openalex.org/T12981 | B9: =RIGHT(A9, LEN(A9) - FIND("/T", A9)) -> T12981 | C9: =CONCAT(B9, ",") -> T12981, | D9: Conservation Techniques and Studies | E9: =CONCATENATE(B9," ",D9,",") -> T12981 Conservation Techniques and Studies, | F9: Arts and Humanities | G9: Social Sciences | H9: H | I9: Humanities & culture | J9: Filter out | K9: Filter | L9: 17772 | M9: =VLOOKUP(A9,'Matching with Cordis'!A$2:D$3447, 4, FALSE) -> 51 | N9: 0.377 | O9: 3 | P9: =AVERAGE(Q9:V9) -> 0.20516667 | Q9: -0.037 | R9: 0.179 | S9: 0.377 | T9: 0.32 | U9: 0.313 | V9: 0.079 | W9: 2012-2015
A10: https://openalex.org/T14213 | B10: =RIGHT(A10, LEN(A10) - FIND("/T", A10)) -> T14213 | C10: =CONCAT(B10, ",") -> T14213, | D10: Global Politics and Economy | E10: =CONCATENATE(B10," ",D10,",") -> T14213 Global Politics and Economy, | F10: Economics, Econometrics and Finance | G10: Social Sciences | H10: P | I10: Social science & policy | J10: Filter out | K10: Review | L10: 5771 | M10: =VLOOKUP(A10,'Matching with Cordis'!A$2:D$3447, 4, FALSE) -> 51 | N10: 0.179 | O10: 0 | P10: =AVERAGE(Q10:V10) -> -0.27666667 | Q10: -0.828 | R10: 0.179 | S10: -0.083 | T10: -0.591 | U10: -0.482 | V10: 0.145 | W10: 2008-2011
A11: https://openalex.org/T12959 | B11: =RIGHT(A11, LEN(A11) - FIND("/T", A11)) -> T12959 | C11: =CONCAT(B11, ",") -> T12959, | D11: Engineering and Materials Science Studies | E11: =CONCATENATE(B11," ",D11,",") -> T12959 Engineering and Materials Science Studies, | F11: Engineering | G11: Physical Sciences | H11: S | I11: Core S&T | J11: Filter out | K11: Keep | L11: 34569 | M11: =VLOOKUP(A11,'Matching with Cordis'!A$2:D$3447, 4, FALSE) -> 51 | N11: 0.005 | O11: 0 | P11: =AVERAGE(Q11:V11) -> -0.29716667 | Q11: -0.491 | R11: -0.531 | S11: -0.14 | T11: -0.34 | U11: -0.286 | V11: 0.005 | W11: 2024-2025
A12: https://openalex.org/T14491 | B12: =RIGHT(A12, LEN(A12) - FIND("/T", A12)) -> T14491 | C12: =CONCAT(B12, ",") -> T14491, | D12: Diverse academic and cultural studies | E12: =CONCATENATE(B12," ",D12,",") -> T14491 Diverse academic and cultural studies, | F12: Economics, Econometrics and Finance | G12: Social Sciences | H12: X | I12: Catch-all / vague | J12: Filter out | K12: Filter | L12: 85811 | M12: =VLOOKUP(A12,'Matching with Cordis'!A$2:D$3447, 4, FALSE) -> 49 | N12: 0.015 | O12: 0 | P12: =AVERAGE(Q12:V12) -> -0.43 | Q12: 0.015 | R12: -0.13 | S12: -0.445 | T12: -0.341 | U12: -1.007 | V12: -0.672 | W12: 2004-2007
A13: https://openalex.org/T10731 | B13: =RIGHT(A13, LEN(A13) - FIND("/T", A13)) -> T10731 | C13: =CONCAT(B13, ",") -> T10731, | D13: Educational Games and Gamification | E13: =CONCATENATE(B13," ",D13,",") -> T10731 Educational Games and Gamification, | F13: Psychology | G13: Social Sciences | H13: E | I13: Education & pedagogy | J13: Filter out | K13: Filter | L13: 58782 | M13: =VLOOKUP(A13,'Matching with Cordis'!A$2:D$3447, 4, FALSE) -> 41 | N13: 1.163 | O13: 6 | P13: =AVERAGE(Q13:V13) -> 0.81716667 | Q13: 1.163 | R13: 1.093 | S13: 0.838 | T13: 0.686 | U13: 0.443 | V13: 0.68 | W13: 2004-2007
... A20: https://openalex.org/T12686 | B20: =RIGHT(A20, LEN(A20) - FIND("/T", A20)) -> T12686 | C20: =CONCAT(B20, ",") -> T12686, | D20: Central European national history | E20: =CONCATENATE(B20," ",D20,",") -> T12686 Central European national history, | F20: Social Sciences | G20: Social Sciences | H20: K | I20: Country/region-specific | J20: Filter out | K20: Filter | L20: 2982 | M20: =VLOOKUP(A20,'Matching with Cordis'!A$2:D$3447, 4, FALSE) -> 22 | N20: -0.199 | O20: 0 | P20: =AVERAGE(Q20:V20) -> -0.3285 | Q20: -0.725 | R20: -0.273 | S20: -0.24 | T20: -0.281 | U20: -0.253 | V20: -0.199 | W20: 2024-2025
A21: https://openalex.org/T13146 | B21: =RIGHT(A21, LEN(A21) - FIND("/T", A21)) -> T13146 | D21: Sustainable Finance and Green Bonds | F21: Economics, Econometrics and Finance | G21: Social Sciences | H21: T | I21: Applied S&T | J21: Keep | K21: Keep | L21: 7159 | M21: =VLOOKUP(A21,'Matching with Cordis'!A$2:D$3447, 4, FALSE) -> 21 | N21: 3.177 | O21: 6 | P21: =AVERAGE(Q21:V21) -> 2.4296667 | Q21: 3.177 | R21: 1.849 | S21: 1.736 | T21: 2.678 | U21: 3.007 | V21: 2.131 | W21: 2004-2007
A22: https://openalex.org/T14296 | B22: =RIGHT(A22, LEN(A22) - FIND("/T", A22)) -> T14296 | C22: =CONCAT(B22, ",") -> T14296, | D22: Climate Change and Sustainable Development | E22: =CONCATENATE(B22," ",D22,",") -> T14296 Climate Change and Sustainable Development, | F22: Environmental Science | G22: Physical Sciences | H22: S | I22: Core S&T | J22: Filter out | K22: Keep | L22: 2824 | M22: =VLOOKUP(A22,'Matching with Cordis'!A$2:D$3447, 4, FALSE) -> 21 | N22: 1.839 | O22: 3 | P22: =AVERAGE(Q22:V22) -> 0.40433333 | Q22: -0.066 | R22: 1.839 | S22: 0.868 | T22: -0.622 | U22: 0.071 | V22: 0.336 | W22: 2008-2011
A23: https://openalex.org/T11714 | B23: =RIGHT(A23, LEN(A23) - FIND("/T", A23)) -> T11714 | D23: Multimodal Machine Learning Applications | F23: Computer Science | G23: Physical Sciences | H23: S | I23: Core S&T | J23: Keep | K23: Keep | L23: 17242 | M23: =VLOOKUP(A23,'Matching with Cordis'!A$2:D$3447, 4, FALSE) -> 17 | N23: 3.737 | O23: 6 | P23: =AVERAGE(Q23:V23) -> 2.4191667 | Q23: 2.52 | R23: 3.737 | S23: 2.703 | T23: 3.188 | U23: 1.984 | V23: 0.383 | W23: 2008-2011
A24: https://openalex.org/T11776 | B24: =RIGHT(A24, LEN(A24) - FIND("/T", A24)) -> T11776 | C24: =CONCAT(B24, ",") -> T11776, | D24: Irish and British Studies | E24: =CONCATENATE(B24," ",D24,",") -> T11776 Irish and British Studies, | F24: Social Sciences | G24: Social Sciences | H24: K | I24: Country/region-specific | J24: Filter out | K24: Filter | L24: 62929 | M24: =VLOOKUP(A24,'Matching with Cordis'!A$2:D$3447, 4, FALSE) -> 20 | N24: -0.522 | O24: 0 | P24: =AVERAGE(Q24:V24) -> -0.67466667 | Q24: -0.522 | R24: -0.861 | S24: -0.592 | T24: -0.622 | U24: -0.872 | V24: -0.579 | W24: 2004-2007
A25: https://openalex.org/T11765 | B25: =RIGHT(A25, LEN(A25) - FIND("/T", A25)) -> T11765 | D25: Circular RNAs in diseases | F25: Biochemistry, Genetics and Molecular Biology | G25: Life Sciences | H25: B | I25: Biomedical research | J25: Keep | K25: Keep | L25: 20510 | M25: =VLOOKUP(A25,'Matching with Cordis'!A$2:D$3447, 4, FALSE) -> 3 | N25: 4.987 | O25: 5 | P25: =AVERAGE(Q25:V25) -> 2.3778333 | Q25: 4.987 | R25: 3.796 | S25: 2.279 | T25: 1.789 | U25: 1.174 | V25: 0.242 | W25: 2004-2007
A26: https://openalex.org/T13298 | B26: =RIGHT(A26, LEN(A26) - FIND("/T", A26)) -> T13298 | C26: =CONCAT(B26, ",") -> T13298, | D26: Solar Energy Systems and Technologies | E26: =CONCATENATE(B26," ",D26,",") -> T13298 Solar Energy Systems and Technologies, | F26: Engineering | G26: Physical Sciences | H26: S | I26: Core S&T | J26: Filter out | K26: Keep | L26: 5038 | M26: =VLOOKUP(A26,'Matching with Cordis'!A$2:D$3447, 4, FALSE) -> 16 | N26: 1.364 | O26: 6 | P26: =AVERAGE(Q26:V26) -> 0.9905 | Q26: 1.102 | R26: 1.279 | S26: 1.364 | T26: 0.915 | U26: 0.769 | V26: 0.514 | W26: 2012-2015
A27: https://openalex.org/T13754 | B27: =RIGHT(A27, LEN(A27) - FIND("/T", A27)) -> T13754 | C27: =CONCAT(B27, ",") -> T13754, | D27: Central European and Russian historical studies | E27: =CONCATENATE(B27," ",D27,",") -> T13754 Central European and Russian historical studies, | F27: Social Sciences | G27: Social Sciences | H27: K | I27: Country/region-specific | J27: Filter out | K27: Filter | L27: 8777 | M27: =VLOOKUP(A27,'Matching with Cordis'!A$2:D$3447, 4, FALSE) -> 16 | N27: 1.016 | O27: 4 | P27: =AVERAGE(Q27:V27) -> 0.52616667 | Q27: -0.154 | R27: 0.471 | S27: 0.909 | T27: 0.637 | U27: 1.016 | V27: 0.278 | W27: 2020-2023
A28: https://openalex.org/T14185 | B28: =RIGHT(A28, LEN(A28) - FIND("/T", A28)) -> T14185 | C28: =CONCAT(B28, ",") -> T14185, | D28: Research, Science, and Academia | E28: =CONCATENATE(B28," ",D28,",") -> T14185 Research, Science, and Academia, | F28: Decision Sciences | G28: Social Sciences | H28: X | I28: Catch-all / vague | J28: Filter out | K28: Filter | L28: 15270 | M28: =VLOOKUP(A28,'Matching with Cordis'!A$2:D$3447, 4, FALSE) -> 16 | N28: 0.496 | O28: 1 | P28: =AVERAGE(Q28:V28) -> -0.513 | Q28: 0.136 | R28: -0.551 | S28: -1.171 | T28: -1.26 | U28: -0.728 | V28: 0.496 | W28: 2024-2025
A29: https://openalex.org/T14411 | B29: =RIGHT(A29, LEN(A29) - FIND("/T", A29)) -> T14411 | C29: =CONCAT(B29, ",") -> T14411, | D29: Undergraduate Neuroscience Education and Research | E29: =CONCATENATE(B29," ",D29,",") -> T14411 Undergraduate Neuroscience Education and Research, | F29: Neuroscience | G29: Life Sciences | H29: E | I29: Education & pedagogy | J29: Filter out | K29: Filter | L29: 479 | M29: =VLOOKUP(A29,'Matching with Cordis'!A$2:D$3447, 4, FALSE) -> 15 | N29: 1.607 | O29: 5 | P29: =AVERAGE(Q29:V29) -> 0.75833333 | Q29: 0.783 | R29: 1.607 | S29: 0.451 | T29: 0.625 | U29: 0.099 | V29: 0.985 | W29: 2008-2011
A30: https://openalex.org/T11636 | B30: =RIGHT(A30, LEN(A30) - FIND("/T", A30)) -> T11636 | D30: Artificial Intelligence in Healthcare and Education | F30: Medicine | G30: Health Sciences | H30: T | I30: Applied S&T | J30: Keep | K30: Keep | L30: 33454 | M30: =VLOOKUP(A30,'Matching with Cordis'!A$2:D$3447, 4, FALSE) -> 35 | N30: 3.664 | O30: 6 | P30: =AVERAGE(Q30:V30) -> 2.2396667 | Q30: 1.156 | R30: 0.91 | S30: 1.387 | T30: 3.664 | U30: 3.454 | V30: 2.867 | W30: 2016-2019
A31: https://openalex.org/T11458 | B31: =RIGHT(A31, LEN(A31) - FIND("/T", A31)) -> T11458 | D31: Advanced Wireless Communication Technologies | F31: Engineering | G31: Physical Sciences | H31: S | I31: Core S&T | J31: Keep | K31: Keep | L31: 21681 | M31: =VLOOKUP(A31,'Matching with Cordis'!A$2:D$3447, 4, FALSE) -> 39 | N31: 5.426 | O31: 5 | P31: =AVERAGE(Q31:V31) -> 2.2265 | Q31: 5.426 | R31: 2.578 | S31: 1.468 | T31: 2.06 | U31: 1.773 | V31: 0.054 | W31: 2004-2007
A32: https://openalex.org/T11342 | B32: =RIGHT(A32, LEN(A32) - FIND("/T", A32)) -> T11342 | D32: Carbon and Quantum Dots Applications | F32: Materials Science | G32: Physical Sciences | H32: S | I32: Core S&T | J32: Keep | K32: Keep | L32: 23715 | M32: =VLOOKUP(A32,'Matching with Cordis'!A$2:D$3447, 4, FALSE) -> 13 | N32: 3.443 | O32: 6 | P32: =AVERAGE(Q32:V32) -> 2.2261667 | Q32: 2.395 | R32: 3.443 | S32: 3.26 | T32: 1.957 | U32: 1.304 | V32: 0.998 | W32: 2008-2011
A33: https://openalex.org/T14292 | B33: =RIGHT(A33, LEN(A33) - FIND("/T", A33)) -> T14292 | C33: =CONCAT(B33, ",") -> T14292, | D33: Migration, Policy, and Dickens Studies | E33: =CONCATENATE(B33," ",D33,",") -> T14292 Migration, Policy, and Dickens Studies, | F33: Social Sciences | G33: Social Sciences | H33: P | I33: Social science & policy | J33: Filter out | K33: Review | L33: 9689 | M33: =VLOOKUP(A33,'Matching with Cordis'!A$2:D$3447, 4, FALSE) -> 15 | N33: 0.136 | O33: 0 | P33: =AVERAGE(Q33:V33) -> -0.38983333 | Q33: -0.535 | R33: -0.071 | S33: -0.322 | T33: -0.807 | U33: -0.74 | V33: 0.136 | W33: 2024-2025
A34: https://openalex.org/T10036 | B34: =RIGHT(A34, LEN(A34) - FIND("/T", A34)) -> T10036 | D34: Advanced Neural Network Applications | F34: Computer Science | G34: Physical Sciences | H34: S | I34: Core S&T | J34: Keep | K34: Keep | L34: 48260 | M34: =VLOOKUP(A34,'Matching with Cordis'!A$2:D$3447, 4, FALSE) -> 13 | N34: 3.459 | O34: 6 | P34: =AVERAGE(Q34:V34) -> 2.1771667 | Q34: 2.607 | R34: 1.457 | S34: 3.459 | T34: 3.168 | U34: 1.896 | V34: 0.476 | W34: 2012-2015
A35: https://openalex.org/T12026 | B35: =RIGHT(A35, LEN(A35) - FIND("/T", A35)) -> T12026 | D35: Explainable Artificial Intelligence (XAI) | F35: Computer Science | G35: Physical Sciences | H35: S | I35: Core S&T | J35: Keep | K35: Keep | L35: 10711 | M35: =VLOOKUP(A35,'Matching with Cordis'!A$2:D$3447, 4, FALSE) -> 36 | N35: 4.041 | O35: 6 | P35: =AVERAGE(Q35:V35) -> 2.1621667 | Q35: 0.595 | R35: 0.753 | S35: 2.962 | T35: 4.041 | U35: 2.927 | V35: 1.695 | W35: 2016-2019
A36: https://openalex.org/T13893 | B36: =RIGHT(A36, LEN(A36) - FIND("/T", A36)) -> T13893 | C36: =CONCAT(B36, ",") -> T13893, | D36: Sustainable Development and Policies | E36: =CONCATENATE(B36," ",D36,",") -> T13893 Sustainable Development and Policies, | F36: Environmental Science | G36: Physical Sciences | H36: S | I36: Core S&T | J36: Filter out | K36: Keep | L36: 751 | M36: =VLOOKUP(A36,'Matching with Cordis'!A$2:D$3447, 4, FALSE) -> 15 | N36: 1.234 | O36: 1 | P36: =AVERAGE(Q36:V36) -> -0.39466667 | Q36: 0.171 | R36: 1.234 | S36: -0.493 | T36: -1.976 | U36: -0.734 | V36: -0.57 | W36: 2008-2011
A37: https://openalex.org/T12432 | B37: =RIGHT(A37, LEN(A37) - FIND("/T", A37)) -> T12432 | C37: =CONCAT(B37, ",") -> T12432, | D37: Arctic and Russian Policy Studies | E37: =CONCATENATE(B37," ",D37,",") -> T12432 Arctic and Russian Policy Studies, | F37: Social Sciences | G37: Social Sciences | H37: K | I37: Country/region-specific | J37: Filter out | K37: Filter | L37: 54598 | M37: =VLOOKUP(A37,'Matching with Cordis'!A$2:D$3447, 4, FALSE) -> 14 | N37: 1.243 | O37: 5 | P37: =AVERAGE(Q37:V37) -> 0.73366667 | Q37: 0.453 | R37: 1.243 | S37: 0.86 | T37: 0.952 | U37: 0.796 | V37: 0.098 | W37: 2008-2011
A38: https://openalex.org/T12627 | B38: =RIGHT(A38, LEN(A38) - FIND("/T", A38)) -> T12627 | D38: Graphene and Nanomaterials Applications | F38: Engineering | G38: Physical Sciences | H38: S | I38: Core S&T | J38: Keep | K38: Keep | L38: 26001 | M38: =VLOOKUP(A38,'Matching with Cordis'!A$2:D$3447, 4, FALSE) -> 28 | N38: 3.966 | O38: 6 | P38: =AVERAGE(Q38:V38) -> 2.1271667 | Q38: 3.217 | R38: 3.966 | S38: 2.2 | T38: 1.385 | U38: 1.065 | V38: 0.93 | W38: 2008-2011
A39: https://openalex.org/T10628 | B39: =RIGHT(A39, LEN(A39) - FIND("/T", A39)) -> T10628 | C39: =CONCAT(B39, ",") -> T10628, | D39: China's Socioeconomic Reforms and Governance | E39: =CONCATENATE(B39," ",D39,",") -> T10628 China's Socioeconomic Reforms and Governance, | F39: Social Sciences | G39: Social Sciences | H39: K | I39: Country/region-specific | J39: Filter out | K39: Filter | L39: 42548 | M39: =VLOOKUP(A39,'Matching with Cordis'!A$2:D$3447, 4, FALSE) -> 14 | N39: -0.018 | O39: 0 | P39: =AVERAGE(Q39:V39) -> -0.069333333 | Q39: -0.03 | R39: -0.062 | S39: -0.194 | T39: -0.018 | U39: -0.018 | V39: -0.094 | W39: 2020-2023
A40: https://openalex.org/T12337 | B40: =RIGHT(A40, LEN(A40) - FIND("/T", A40)) -> T12337 | C40: =CONCAT(B40, ",") -> T12337, | D40: Italian Fascism and Post-war Society | E40: =CONCATENATE(B40," ",D40,",") -> T12337 Italian Fascism and Post-war Society, | F40: Social Sciences | G40: Social Sciences | H40: K | I40: Country/region-specific | J40: Filter out | K40: Filter | L40: 100026 | M40: =VLOOKUP(A40,'Matching with Cordis'!A$2:D$3447, 4, FALSE) -> 14 | N40: 0.092 | O40: 0 | P40: =AVERAGE(Q40:V40) -> -0.31233333 | Q40: -0.399 | R40: -0.402 | S40: -0.362 | T40: -0.134 | U40: -0.669 | V40: 0.092 | W40: 2024-2025
A41: https://openalex.org/T12312 | B41: =RIGHT(A41, LEN(A41) - FIND("/T", A41)) -> T12312 | C41: =CONCAT(B41, ",") -> T12312, | D41: Culture, Economy, and Development Studies | E41: =CONCATENATE(B41," ",D41,",") -> T12312 Culture, Economy, and Development Studies, | F41: Social Sciences | G41: Social Sciences | H41: P | I41: Social science & policy | J41: Filter out | K41: Review | L41: 12287 | M41: =VLOOKUP(A41,'Matching with Cordis'!A$2:D$3447, 4, FALSE) -> 14 | N41: 0.128 | O41: 0 | P41: =AVERAGE(Q41:V41) -> -0.4325 | Q41: 0.128 | R41: 0.024 | S41: -0.513 | T41: -0.621 | U41: -0.752 | V41: -0.861 | W41: 2004-2007
A42: https://openalex.org/T11198 | B42: =RIGHT(A42, LEN(A42) - FIND("/T", A42)) -> T11198 | C42: =CONCAT(B42, ",") -> T11198, | D42: Japanese History and Culture | E42: =CONCATENATE(B42," ",D42,",") -> T11198 Japanese History and Culture, | F42: Social Sciences | G42: Social Sciences | H42: K | I42: Country/region-specific | J42: Filter out | K42: Filter | L42: 88913 | M42: =VLOOKUP(A42,'Matching with Cordis'!A$2:D$3447, 4, FALSE) -> 14 | N42: -0.034 | O42: 0 | P42: =AVERAGE(Q42:V42) -> -0.44716667 | Q42: -0.694 | R42: -0.386 | S42: -0.498 | T42: -0.523 | U42: -0.548 | V42: -0.034 | W42: 2024-2025
A43: https://openalex.org/T14242 | B43: =RIGHT(A43, LEN(A43) - FIND("/T", A43)) -> T14242 | C43: =CONCAT(B43, ",") -> T14242, | D43: Nutrition, Health, and Society Studies | E43: =CONCATENATE(B43," ",D43,",") -> T14242 Nutrition, Health, and Society Studies, | F43: Agricultural and Biological Sciences | G43: Life Sciences | H43: T | I43: Applied S&T | J43: Filter out | K43: Keep | L43: 2767 | M43: =VLOOKUP(A43,'Matching with Cordis'!A$2:D$3447, 4, FALSE) -> 14 | N43: 0.995 | O43: 1 | P43: =AVERAGE(Q43:V43) -> -0.71683333 | Q43: -0.528 | R43: 0.995 | S43: -2.044 | T43: -0.783 | U43: -1.423 | V43: -0.518 | W43: 2008-2011
A44: https://openalex.org/T11133 | B44: =RIGHT(A44, LEN(A44) - FIND("/T", A44)) -> T11133 | D44: UAV Applications and Optimization | F44: Engineering | G44: Physical Sciences | H44: S | I44: Core S&T | J44: Keep | K44: Keep | L44: 20055 | M44: =VLOOKUP(A44,'Matching with Cordis'!A$2:D$3447, 4, FALSE) -> 81 | N44: 3.023 | O44: 6 | P44: =AVERAGE(Q44:V44) -> 2.048 | Q44: 3.023 | R44: 1.324 | S44: 2.054 | T44: 3.021 | U44: 2.137 | V44: 0.729 | W44: 2004-2007
A45: https://openalex.org/T13819 | B45: =RIGHT(A45, LEN(A45) - FIND("/T", A45)) -> T13819 | C45: =CONCAT(B45, ",") -> T13819, | D45: Collaborative and Sustainable Housing Initiatives | E45: =CONCATENATE(B45," ",D45,",") -> T13819 Collaborative and Sustainable Housing Initiatives, | F45: Social Sciences | G45: Social Sciences | H45: P | I45: Social science & policy | J45: Filter out | K45: Review | L45: 2241 | M45: =VLOOKUP(A45,'Matching with Cordis'!A$2:D$3447, 4, FALSE) -> 13 | N45: 1.139 | O45: 5 | P45: =AVERAGE(Q45:V45) -> 0.71716667 | Q45: 1.122 | R45: 0.882 | S45: 1.139 | T45: 0.62 | U45: 0.275 | V45: 0.265 | W45: 2012-2015
A46: https://openalex.org/T13894 | B46: =RIGHT(A46, LEN(A46) - FIND("/T", A46)) -> T13894 | C46: =CONCAT(B46, ",") -> T13894, | D46: Indian Economic and Social Development | E46: =CONCATENATE(B46," ",D46,",") -> T13894 Indian Economic and Social Development, | F46: Economics, Econometrics and Finance | G46: Social Sciences | H46: K | I46: Country/region-specific | J46: Filter out | K46: Filter | L46: 29668 | M46: =VLOOKUP(A46,'Matching with Cordis'!A$2:D$3447, 4, FALSE) -> 13 | N46: 0.35 | O46: 2 | P46: =AVERAGE(Q46:V46) -> 0.0585 | Q46: 0.35 | R46: -0.223 | S46: 0.046 | T46: -0.261 | U46: 0.09 | V46: 0.349 | W46: 2004-2007
...

Sheet Sheet2
A1: Topic ID
A2: T13703
A3: T13436
A4: T13656
A5: T10289
A6: T14152
A7: T14347
A8: T14440
A9: T12981
A10: T14213
A11: T12959
A12: T14491
... A812: T13064

Sheet Monitoring progress
D2: =B2/B4 -> 0.1795837

Sheet Matching with Cordis
A1: topic_id | B1: topic_name | C1: domain_name | D1: n_projects | E1: avg_frontier
A2: https://openalex.org/T11524 | B2: Advanced Aircraft Design and Technologies | C2: Physical Sciences | D2: 294 | E2: 0.43663668
A3: https://openalex.org/T10763 | B3: Digital Transformation in Industry | C3: Physical Sciences | D3: 255 | E3: 2.793644
A4: https://openalex.org/T14147 | B4: Innovative Approaches in Technology and Social Development | C4: Social Sciences | D4: 241 | E4: 0.40904573
A5: https://openalex.org/T13726 | B5: International Science and Diplomacy | C5: Social Sciences | D5: 227 | E5: -0.012300117
A6: https://openalex.org/T11489 | B6: Air Traffic Management and Optimization | C6: Physical Sciences | D6: 217 | E6: 0.25006489
A7: https://openalex.org/T10119 | B7: Sustainability and Climate Change Governance | C7: Physical Sciences | D7: 216 | E7: 0.47987034
A8: https://openalex.org/T11185 | B8: Integrated Energy Systems Optimization | C8: Physical Sciences | D8: 210 | E8: 1.4605274
A9: https://openalex.org/T13240 | B9: Bioeconomy and Sustainability Development | C9: Life Sciences | D9: 210 | E9: 1.1053384
A10: https://openalex.org/T11190 | B10: 3D Printing in Biomedical Research | C10: Physical Sciences | D10: 205 | E10: 0.56487297
A11: https://openalex.org/T10184 | B11: Plant Molecular Biology Research | C11: Life Sciences | D11: 203 | E11: -0.2354159
A12: https://openalex.org/T10603 | B12: Smart Grid Energy Management | C12: Physical Sciences | D12: 198 | E12: 1.1817511
A13: https://openalex.org/T12414 | B13: Coastal and Marine Management | C13: Physical Sciences | D13: 193 | E13: 0.29116701
... A3448: https://openalex.org/T13370 | B3448: Diverse Scientific and Economic Studies | C3448: Social Sciences | D3448: 1 | E3448: -2.3684442

Sheet Taxonomy
A1: Code | B1: Category | C1: Count | D1: % of total | E1: Description | F1: Claude commentary
A2: S | B2: Core S&T | C2: 1484 | D2: 32.9 | E2: Hard science, engineering, computer science, mathematics, materials, physics, chemistry, energy. | F2: Core ACCORD scope.
A3: B | B3: Biomedical research | C3: 1050 | D3: 23.3 | E3: Molecular, cellular, genetic, pharmacological research. Disease mechanisms, drug development, -omics. | F3: Core ACCORD scope.
A4: T | B4: Applied S&T | C4: 297 | D4: 6.6 | E4: S&T methods applied to sectors: AI in healthcare, smart agriculture, digital transformation, computational social science. | F4: Core ACCORD scope.
A5: P | B5: Social science & policy | C5: 568 | D5: 12.6 | E5: Law, sociology, political science, economics (qualitative), migration, gender studies. May contain some policy-relevant R&I content. | F5: Case-by-case; some topics may have S&T relevance.
A6: Y | B6: Psychology & behavioural | C6: 118 | D6: 2.6 | E6: Therapy, psychometrics, cognitive/behavioural research. Some neuroscience overlap. | F6: Case-by-case; some topics may have S&T relevance.
A7: C | B7: Clinical & health practice | C7: 111 | D7: 2.5 | E7: Nursing, patient care, health services, occupational health, rehabilitation. Practice-oriented. | F7: Case-by-case; some topics may have S&T relevance.
A8: V | B8: Crisis-driven (COVID) | C8: 22 | D8: 0.5 | E8: Pandemic-specific topics. Genuine research but exogenous shock distorting temporal comparisons. | F8: Case-by-case; some topics may have S&T relevance.
A9: E | B9: Education & pedagogy | C9: 210 | D9: 4.7 | E9: Teaching methods, e-learning, curriculum, school systems, student outcomes. High publication volume growth but not S&T frontier. | F9: Persistent top-quartile noise; not S&T frontier.
A10: H | B10: Humanities & culture | C10: 238 | D10: 5.3 | E10: Literature, history, theology, philosophy, art, archaeology, cultural studies. Not S&T research. | F10: Persistent top-quartile noise; not S&T frontier.
A11: M | B11: Business & management | C11: 168 | D11: 3.7 | E11: Corporate governance, HR, marketing, supply chain, leadership. Not S&T research. | F11: Persistent top-quartile noise; not S&T frontier.
A12: X | B12: Catch-all / vague | C12: 101 | D12: 2.2 | E12: Generic OA categories with no coherent domain. Aggregation artefacts. | F12: Persistent top-quartile noise; not S&T frontier.
A13: K | B13: Country/region-specific | C13: 127 | D13: 2.8 | E13: National/regional society, politics, law, history, culture topics. Reflects country-level publication growth, not global S&T frontier. Applied consistently across ALL geographies. | F13: Persistent top-quartile noise; not S&T frontier.
A14: L | B14: Sports, tourism & leisure | C14: 22 | D14: 0.5 | E14: Sports science, tourism management, hospitality. Not S&T research. | F14: Persistent top-quartile noise; not S&T frontier.

Sheet topic_count_GBQ
A1: topic_id | B1: num_works | C1: Topic ID no url
A2: 10001 | B2: 150218 | C2: T10001
A3: 10002 | B3: 74259 | C3: T10002
A4: 10003 | B4: 70644 | C4: T10003
A5: 10004 | B5: 77972 | C5: T10004
A6: 10005 | B6: 62930 | C6: T10005
A7: 10006 | B7: 69257 | C7: T10006
A8: 10007 | B8: 85649 | C8: T10007
A9: 10008 | B9: 60498 | C9: T10008
A10: 10009 | B10: 74582 | C10: T10009
A11: 10010 | B11: 93414 | C11: T10010
A12: 10011 | B12: 18633 | C12: T10011
A13: 10012 | B13: 38194 | C13: T10012
... A4517: 14521 | B4517: 38368 | C4517: T14521
